<?xml version="1.0" ?>
<robot name="avb_bot" xmlns:xacro="https://www.ros.org/wiki/xacro" >
 <material name="black">
    <color rgba="0.0 0.0 0.0 1.0"/>
  </material>
  <material name="blue">
    <color rgba="0.203125 0.23828125 0.28515625 1.0"/>
  </material>
<!-- gazebo plugin -->

<gazebo>
    <plugin filename="libgazebo_ros_diff_drive.so" name="differential_drive_controller">
      <alwaysOn>true</alwaysOn>
      <updateRate>20</updateRate>
      <leftJoint>left_wheel_joint</leftJoint>
      <rightJoint>right_wheel_joint</rightJoint>
      <wheelSeparation>0.4</wheelSeparation>
      <wheelDiameter>0.14</wheelDiameter>
      <torque>0.01</torque>
      <commandTopic>cmd_vel</commandTopic>
      <odometryTopic>odom</odometryTopic>
      <odometryFrame>odom</odometryFrame>
      <robotBaseFrame>base_link</robotBaseFrame>
    </plugin>
  </gazebo>

  <gazebo reference="base_link">
    <material>Gazebo/Blue</material>
  </gazebo>
  <gazebo reference="right_wheel">
    <material>Gazebo/Black</material>
  </gazebo>
  <gazebo reference="left_wheel">
    <material>Gazebo/Black</material>
  </gazebo>


 <gazebo reference="sensor_laser">
    <sensor type="ray" name="head_hokuyo_sensor">
      <pose>0 0 0 0 0 0</pose>
      <visualize>true</visualize>
      <update_rate>20</update_rate>
      <ray>
        <scan>
          <horizontal>
            <samples>720</samples>
            <resolution>1</resolution>
            <min_angle>-1.570796</min_angle>
            <max_angle>1.570796</max_angle>
          </horizontal>
        </scan>
        <range>
          <min>0.10</min>
          <max>10.0</max>
          <resolution>0.01</resolution>
        </range>
        <noise>
          <type>gaussian</type>
          <mean>0.0</mean>
          <stddev>0.01</stddev>
        </noise>
      </ray>
      <plugin name="gazebo_ros_head_hokuyo_controller" filename="libgazebo_ros_laser.so">
        <topicName>/avb_bot/laser/scan</topicName>
        <frameName>sensor_laser</frameName>
      </plugin>
    </sensor>
  </gazebo> 

 

<!-- base_link -->

<link name="base_link">
    <visual>
      <origin rpy="0 0 0" xyz="0 0 0"/>
      <geometry>
        <cylinder length="0.2" radius="0.2"/>
      </geometry>
      <material name="blue"/>
    </visual>

    <collision name="collision_chassis">
     <geometry>
      <cylinder length="0.2" radius="0.2"/>
     </geometry>
    </collision>
    <inertial>
     <mass value="1.0"/>
      <inertia ixx="0.0133" iyy="0.0133" izz="0.02"
      ixy="0" ixz="0" iyz="0"/>
    </inertial>
  </link>
  

  <!--   Link for right wheel  -->
  <link name="right_wheel">
   <visual name="link_right_wheel_visual">
    <origin rpy="0 1.5707 1.5707" xyz="0 0 0"/>
    <geometry>
     <cylinder length="0.05" radius="0.070"/>
    </geometry>
    <material name="black"/>
   </visual>

   <collision name="link_right_wheel_collision">
      <origin rpy="0 1.5707 1.5707" xyz="0 0 0" />
      <geometry>
        <cylinder length="0.05" radius="0.070"/>
      </geometry>
    </collision>

   <inertial>
    <mass value="0.2"/>
    <origin rpy="0 1.5707 1.5707" xyz="0 0 0"/>
    <inertia ixx="1.433e-4" iyy="1.433e-4" izz="2.45e-4"
      ixy="0" ixz="0" iyz="0"/>
   </inertial>
  </link>

  

  <!--   Joint for right wheel  -->

  <joint name="right_wheel_joint" type="continuous">
   <axis xyz="0 -1 0"/>
   <parent link="base_link"/>
   <child link="right_wheel"/>
   <origin rpy="0 0 0" xyz="-0.04 0.2 -0.08"/>
   <limit effort="10000" velocity="1000"/>
   <joint_properties damping="1.0" friction="1.0" />
  </joint>

  <!--   Link for left wheel --> 
  
  <link name="left_wheel">
   <visual name="link_left_wheel_visual">
    <origin rpy="0 1.5707 1.5707" xyz="0 0 0"/>
    <geometry>
     <cylinder length="0.05" radius="0.070"/>
    </geometry>
    <material name="black"/>
   </visual>

   <collision name="link_right_wheel_collision">
      <origin rpy="0 1.5707 1.5707" xyz="0 0 0" />
      <geometry>
        <cylinder length="0.05" radius="0.070"/>
      </geometry>
    </collision>

   <inertial>
    <mass value="0.2"/>
    <origin rpy="0 1.5707 1.5707" xyz="0 0 0"/>
    <inertia ixx="1.433e-4" iyy="1.433e-4" izz="2.45e-4"
      ixy="0" ixz="0" iyz="0"/>
   </inertial>
  </link>
  

   <!--  Joint for left wheel -->  

  <joint name="left_wheel_joint" type="continuous">
   <axis xyz="0 -1 0"/>
   <parent link="base_link"/>
   <child link="left_wheel"/>
   <origin rpy="0 0 0" xyz="-0.04 -0.2 -0.08"/>
   <limit effort="10000" velocity="1000"/>
   <joint_properties damping="1.0" friction="1.0" />
  </joint>

  <!-- link for caster wheel -->
  <link name="caster_wheel">
   <visual name="caster_visual">
    <origin rpy="0 0 0" xyz="0 0 0"/>
    <geometry>
     <sphere radius="0.05"/>
    </geometry>
    <material name="black"/>
   </visual>
   
   
   <collision name="caster_collsion">
    <origin rpy="0 0 0" xyz="0 0 0"/>
    <geometry>
     <sphere radius="0.05"/>
    </geometry>
   </collision>

   
   <inertial>
    <mass value="0.1"/>
    <origin rpy="0 0 0" xyz="0 0 0"/>
    <inertia ixx="1e-4" ixy="0" ixz="0" iyy="1e-4" iyz="0" izz="1e-4"/>
   </inertial> 
  </link>

 <joint name="caster_joint" type="continuous">
  <axis xyz="0 -1 0"/>
  <parent link="base_link"/>
  <child link="caster_wheel"/>
  <origin rpy="0 0 0" xyz="0.15 0 -0.1"/>
  <limit effort="10000" velocity="1000"/>
  <joint_properties damping="1.0" friction="1.0" />
 </joint> 

<!-- Laser Sensor link -->
 <link name="sensor_laser">
    <inertial>
      <origin xyz="0 0 0" rpy="0 0 0" />
      <mass value="0.1" />
      <inertia ixx="1.4583e-4" ixy="0" ixz="0" iyy="1.4583e-4" iyz="0" izz="1.25e-4"/>
    </inertial>

    <visual>
      <origin xyz="0 0 0" rpy="0 0 0" />
      <geometry>
        <cylinder radius="0.05" length="0.1"/>
      </geometry>
    </visual>

    <collision>
      <origin xyz="0 0 0" rpy="0 0 0"/>
      <geometry>
        <cylinder radius="0.05" length="0.1"/>
      </geometry>
    </collision>
  </link>

  <joint name="joint_sensor_laser" type="fixed">
    <origin xyz="0.12 0 0.1" rpy="0 0 0"/>
    <parent link="base_link"/>
    <child link="sensor_laser"/>
  </joint>


</robot>


